Workbook

Sheet Cover
A1: Salesforce, Inc. (NYSE: CRM) - 3-Statement Model & DCF
A2: Built Oct 14, 2026. Base year FY2026A (Jan 31, 2026); forecast FY2027E-FY2031E. $ in millions.
A4: Key outputs (live scenario)
A5: Active scenario | B5: =Assumptions!C4 -> Base
A6: Implied value per share - blended ($) | B6: =DCF!D74 -> 230.36441
A7: Implied value per share - perpetuity ($) | B7: =DCF!B74 -> 199.12476
A8: Implied value per share - exit multiple ($) | B8: =DCF!C74 -> 261.60407
A9: Current share price ($) | B9: =DCF!B6 -> 235.95
A10: Upside / (downside) - blended | B10: =DCF!D76 -> -0.02367276
A11: WACC | B11: =DCF!B30 -> 0.10304449
A12: FY27E revenue / within guidance? | B12: =IS!F7 -> 46214.96 | C12: ='Revenue Build'!B29 -> YES
A13: FY31E revenue | B13: =IS!J7 -> 67037.019
A14: FY26A-FY31E revenue CAGR | B14: =(IS!J7/IS!E7)^(1/5)-1 -> 0.10052778
A15: FY31E GAAP operating margin | B15: =IS!J22 -> 0.24890527
A16: FY31E non-GAAP operating margin | B16: =IS!J44 -> 0.3445876
A17: FY31E free cash flow (CFO - capex) | B17: =CF!J32 -> 20151.758
A19: Model integrity checks
A20: Balance sheet balances in every year? | B20: =IF(SUMPRODUCT(ABS(BS!D31:J31))<0.01,"OK","ERROR") -> OK
A21: Forecast cash stays positive? | B21: =IF(MIN(BS!F5:J5)>0,"OK","NEGATIVE CASH") -> OK
A22: Historical CF ties to reported CFO? | B22: =IF(SUMPRODUCT(ABS(CF!B14:E14-CF!B15:E15))<0.01,"OK","ERROR") -> OK
A23: WACC > terminal growth? | B23: =IF(DCF!B30>DCF!B33,"OK","ERROR") -> OK
A25: Scenario snapshot (values pasted at build; re-run by changing Assumptions!B4)
B26: Downside | C26: Base | D26: Upside
A27: Value per share - blended ($) | B27: 179.9113 | C27: 230.3644 | D27: 265.0172
A28: Upside / (downside) | B28: -0.2375 | C28: -0.0237 | D28: 0.1232
A29: FY31E revenue ($mm) | B29: 58522.135 | C29: 67037.019 | D29: 72624.805
A30: FY31E GAAP operating margin | B30: 0.2241 | C30: 0.2489 | D30: 0.2642
A31: FY31E free cash flow ($mm) | B31: 15916.548 | C31: 20151.758 | D31: 23023.826
A32: Snapshot uses base valuation inputs (WACC, terminal growth, exit multiple) in all three scenarios.
A34: How to use
A35: 1. Flip the scenario on Assumptions!B4 (1 Downside, 2 Base, 3 Upside). Everything recalculates.
A36: 2. Revenue engine: Revenue Build. Subscription revenue = prior year-end cRPO x conversion ratio; cRPO growth is the main lever.
A37: 3. Costs and working capital are % of revenue on Assumptions; historical ratios are listed next to each input.
A38: 4. Statements: IS -> BS -> CF. Ending cash on CF feeds BS cash; BS!31 must be 0 in every year.
A39: 5. DCF: B16 toggles whether SBC is treated as a real cost (default 1 = yes). Sensitivity tables at DCF!A80 and A89.
A40: Colour code: blue = hardcoded input, black = formula, green = link to another sheet, yellow = key lever.

Sheet Assumptions
A1: Salesforce (CRM) - Forecast Assumptions
A2: Blue = hardcoded input. Yellow = key lever. Live rows (black) pick the active scenario with CHOOSE.
A4: Scenario selector (1 = Downside, 2 = Base, 3 = Upside) | B4: 2 | C4: =CHOOSE($B$4,"Downside","Base","Upside") -> Base
A6: ($ in millions, FY ends Jan 31) | F6: FY2027E | G6: FY2028E | H6: FY2029E | I6: FY2030E | J6: FY2031E | K6: Rationale / source
A9: Revenue drivers
A10: Current RPO growth - Downside | F10: 0.09 | G10: 0.07 | H10: 0.06 | I10: 0.05 | J10: 0.045
A11: Current RPO growth - Base | F11: 0.12 | G11: 0.105 | H11: 0.1 | I11: 0.09 | J11: 0.08 | K11: Q2 FY27 cRPO +14% Y/Y (incl. Informatica); Q3 guide ~14%. Base fades as acquisition lap ends; FY30 ~ mgmt $63B target
A12: Current RPO growth - Upside | F12: 0.14 | G12: 0.13 | H12: 0.12 | I12: 0.11 | J12: 0.1
A13: Current RPO growth - LIVE | F13: =CHOOSE($B$4,F10,F11,F12) -> 0.12 | G13: =CHOOSE($B$4,G10,G11,G12) -> 0.105 | H13: =CHOOSE($B$4,H10,H11,H12) -> 0.1 | I13: =CHOOSE($B$4,I10,I11,I12) -> 0.09 | J13: =CHOOSE($B$4,J10,J11,J12) -> 0.08
A14: Next-year sub. revenue / prior-year-end cRPO (x) | F14: 1.257 | G14: 1.255 | H14: 1.25 | I14: 1.25 | J14: 1.25 | K14: Historical: FY24 1.32x, FY25 1.29x, FY26 1.30x. FY27 1.257x reproduces guidance (sub growth slightly >12%)
A15: cRPO as % of total RPO | F15: 0.485 | G15: 0.485 | H15: 0.485 | I15: 0.485 | J15: 0.485 | K15: Historical: 50.6% / 48.5% / 47.6% / 48.5% (Jan-23 to Jan-26). Memo only - drives total RPO KPI
A16: Professional services growth - Downside | F16: -0.06 | G16: -0.06 | H16: -0.06 | I16: -0.06 | J16: -0.06
A17: Professional services growth - Base | F17: -0.02 | G17: -0.02 | H17: -0.02 | I17: -0.02 | J17: -0.02 | K17: PS revenue fell 4.5% FY25 and 3.6% FY26; low strategic priority
A18: Professional services growth - Upside | F18: 0.02 | G18: 0.02 | H18: 0.02 | I18: 0.02 | J18: 0.02
A19: Professional services growth - LIVE | F19: =CHOOSE($B$4,F16,F17,F18) -> -0.02 | G19: =CHOOSE($B$4,G16,G17,G18) -> -0.02 | H19: =CHOOSE($B$4,H16,H17,H18) -> -0.02 | I19: =CHOOSE($B$4,I16,I17,I18) -> -0.02 | J19: =CHOOSE($B$4,J16,J17,J18) -> -0.02
A21: Cost structure (GAAP, SBC embedded in each line)
A22: Cost of sub & support (% of sub rev) - Downside | F22: 0.185 | G22: 0.185 | H22: 0.185 | I22: 0.185 | J22: 0.185 | K22: Downside: AI inference/compute costs pressure gross margin
A23: Cost of sub & support (% of sub rev) - Base | F23: 0.175 | G23: 0.175 | H23: 0.175 | I23: 0.175 | J23: 0.175 | K23: Historical: 20.1% / 19.0% / 17.4% / 17.3%
A24: Cost of sub & support (% of sub rev) - Upside | F24: 0.17 | G24: 0.17 | H24: 0.17 | I24: 0.17 | J24: 0.17
A25: Cost of sub & support (% of sub rev) - LIVE | F25: =CHOOSE($B$4,F22,F23,F24) -> 0.175 | G25: =CHOOSE($B$4,G22,G23,G24) -> 0.175 | H25: =CHOOSE($B$4,H22,H23,H24) -> 0.175 | I25: =CHOOSE($B$4,I22,I23,I24) -> 0.175 | J25: =CHOOSE($B$4,J22,J23,J24) -> 0.175
A26: Cost of prof. services (% of PS rev) | F26: 1.15 | G26: 1.15 | H26: 1.15 | I26: 1.15 | J26: 1.15 | K26: Historical: 109% / 102% / 110% / 116% - PS runs at a loss
A27: R&D (% of revenue) | F27: 0.148 | G27: 0.148 | H27: 0.148 | I27: 0.148 | J27: 0.148 | K27: Historical: 16.1% / 14.1% / 14.5% / 14.4%; FY27 adds Informatica R&D
A28: Sales & marketing (% of revenue) - Downside | F28: 0.348 | G28: 0.348 | H28: 0.346 | I28: 0.344 | J28: 0.342
A29: Sales & marketing (% of revenue) - Base | F29: 0.345 | G29: 0.34 | H29: 0.335 | I29: 0.33 | J29: 0.325 | K29: Historical: 43.1% / 36.9% / 35.0% / 34.5%. Base = ~50bp/yr efficiency
A30: Sales & marketing (% of revenue) - Upside | F30: 0.343 | G30: 0.335 | H30: 0.327 | I30: 0.319 | J30: 0.311
A31: Sales & marketing (% of revenue) - LIVE | F31: =CHOOSE($B$4,F28,F29,F30) -> 0.345 | G31: =CHOOSE($B$4,G28,G29,G30) -> 0.34 | H31: =CHOOSE($B$4,H28,H29,H30) -> 0.335 | I31: =CHOOSE($B$4,I28,I29,I30) -> 0.33 | J31: =CHOOSE($B$4,J28,J29,J30) -> 0.325
A32: G&A (% of revenue) | F32: 0.074 | G32: 0.073 | H32: 0.072 | I32: 0.071 | J32: 0.07 | K32: Historical: 8.1% / 7.3% / 7.5% / 7.2%
A33: Restructuring (% of revenue) | F33: 0.01 | G33: 0.005 | H33: 0.005 | I33: 0.005 | J33: 0.005 | K33: FY26 1.4%; assume tapering
A34: Stock-based comp (% of revenue) - memo, already in opex | F34: 0.083 | G34: 0.083 | H34: 0.083 | I34: 0.083 | J34: 0.083 | K34: Historical: 10.5% / 8.0% / 8.4% / 8.5%
A35: Amortization of acquired intangibles ($mm) | F35: 1900 | G35: 1700 | H35: 1500 | I35: 1200 | J35: 900 | K35: FY26 $1,687mm; Informatica adds a full year in FY27, then roll-off. Capped at remaining balance
A36: Depreciation (% of beginning PP&E) | F36: 0.2 | G36: 0.2 | H36: 0.2 | I36: 0.2 | J36: 0.2 | K36: Owned PP&E only. Finance-lease depreciation and lease principal payments are excluded (roughly offset)
A37: Capex (% of revenue) | F37: 0.015 | G37: 0.015 | H37: 0.015 | I37: 0.015 | J37: 0.015 | K37: FY27 guidance: ~1.5% of revenue
A38: Effective tax rate | F38: 0.223 | G38: 0.215 | H38: 0.215 | I38: 0.215 | J38: 0.215 | K38: FY27 GAAP guidance ~22.3%
A39: Interest rate on average debt | F39: 0.045 | G39: 0.045 | H39: 0.045 | I39: 0.045 | J39: 0.045 | K39: Blend of legacy low-coupon notes and 2026 issuance
A40: Yield on beginning cash & marketable securities | F40: 0.0375 | G40: 0.0375 | H40: 0.0375 | I40: 0.0375 | J40: 0.0375
A42: Working capital
A43: Accounts receivable (days of revenue, DSO) | F43: 126 | G43: 126 | H43: 126 | I43: 126 | J43: 126 | K43: FY26: 126 days (Jan year-end is peak billing season)
A44: Capitalized contract costs (% of revenue) | F44: 0.122 | G44: 0.122 | H44: 0.122 | I44: 0.122 | J44: 0.122 | K44: FY26: 12.2% (current + noncurrent)
A45: Prepaid & other current assets (% of revenue) | F45: 0.054 | G45: 0.054 | H45: 0.054 | I45: 0.054 | J45: 0.054 | K45: FY26: 5.4%
A46: AP, accrued & other liabilities (% of revenue) | F46: 0.199 | G46: 0.199 | H46: 0.199 | I46: 0.199 | J46: 0.199 | K46: FY26: 19.9%
...

Sheet Revenue Build
A1: Salesforce - RPO-Driven Revenue Build
A2: Subscription revenue = prior year-end current RPO x conversion ratio. cRPO is the bookings engine.
A4: ($ in millions, FY ends Jan 31) | B4: FY2023A | C4: FY2024A | D4: FY2025A | E4: FY2026A | F4: FY2027E | G4: FY2028E | H4: FY2029E | I4: FY2030E | J4: FY2031E
A6: Remaining performance obligation
A7: Current RPO (cRPO), year-end | B7: 24600 | C7: 27600 | D7: 30200 | E7: 35100 | F7: =E7*(1+Assumptions!F13) -> 39312 | G7: =F7*(1+Assumptions!G13) -> 43439.76 | H7: =G7*(1+Assumptions!H13) -> 47783.736 | I7: =H7*(1+Assumptions!I13) -> 52084.272 | J7: =I7*(1+Assumptions!J13) -> 56251.014
A8: cRPO growth | C8: =C7/B7-1 -> 0.12195122 | D8: =D7/C7-1 -> 0.094202899 | E8: =E7/D7-1 -> 0.16225166 | F8: =F7/E7-1 -> 0.12 | G8: =G7/F7-1 -> 0.105 | H8: =H7/G7-1 -> 0.1 | I8: =I7/H7-1 -> 0.09 | J8: =J7/I7-1 -> 0.08
A9: Total RPO, year-end | B9: 48600 | C9: 56900 | D9: 63400 | E9: 72400 | F9: =F7/Assumptions!F15 -> 81055.67 | G9: =G7/Assumptions!G15 -> 89566.515 | H9: =H7/Assumptions!H15 -> 98523.167 | I9: =I7/Assumptions!I15 -> 107390.25 | J9: =J7/Assumptions!J15 -> 115981.47
A10: cRPO as % of total RPO | B10: =B7/B9 -> 0.50617284 | C10: =C7/C9 -> 0.48506151 | D10: =D7/D9 -> 0.47634069 | E10: =E7/E9 -> 0.48480663 | F10: =F7/F9 -> 0.485 | G10: =G7/G9 -> 0.485 | H10: =H7/H9 -> 0.485 | I10: =I7/I9 -> 0.485 | J10: =J7/J9 -> 0.485
A12: Revenue
A13: Subscription & support revenue | B13: 29021 | C13: 32537 | D13: 35679 | E13: 39388 | F13: =E7*Assumptions!F14 -> 44120.7 | G13: =F7*Assumptions!G14 -> 49336.56 | H13: =G7*Assumptions!H14 -> 54299.7 | I13: =H7*Assumptions!I14 -> 59729.67 | J13: =I7*Assumptions!J14 -> 65105.34
A14: growth | C14: =C13/B13-1 -> 0.12115365 | D14: =D13/C13-1 -> 0.096566985 | E14: =E13/D13-1 -> 0.10395471 | F14: =F13/E13-1 -> 0.12015589 | G14: =G13/F13-1 -> 0.11821798 | H14: =H13/G13-1 -> 0.10059761 | I14: =I13/H13-1 -> 0.1 | J14: =J13/I13-1 -> 0.09
A15: Conversion: sub revenue / prior-year-end cRPO | C15: =C13/B7 -> 1.3226423 | D15: =D13/C7 -> 1.2927174 | E15: =E13/D7 -> 1.3042384 | F15: =F13/E7 -> 1.257 | G15: =G13/F7 -> 1.255 | H15: =H13/G7 -> 1.25 | I15: =I13/H7 -> 1.25 | J15: =J13/I7 -> 1.25
A16: Professional services & other revenue | B16: 2331 | C16: 2320 | D16: 2216 | E16: 2137 | F16: =E16*(1+Assumptions!F19) -> 2094.26 | G16: =F16*(1+Assumptions!G19) -> 2052.3748 | H16: =G16*(1+Assumptions!H19) -> 2011.3273 | I16: =H16*(1+Assumptions!I19) -> 1971.1008 | J16: =I16*(1+Assumptions!J19) -> 1931.6787
A17: growth | C17: =C16/B16-1 -> -0.0047190047 | D17: =D16/C16-1 -> -0.044827586 | E17: =E16/D16-1 -> -0.035649819 | F17: =F16/E16-1 -> -0.02 | G17: =G16/F16-1 -> -0.02 | H17: =H16/G16-1 -> -0.02 | I17: =I16/H16-1 -> -0.02 | J17: =J16/I16-1 -> -0.02
A18: Total revenue | B18: =B13+B16 -> 31352 | C18: =C13+C16 -> 34857 | D18: =D13+D16 -> 37895 | E18: =E13+E16 -> 41525 | F18: =F13+F16 -> 46214.96 | G18: =G13+G16 -> 51388.935 | H18: =H13+H16 -> 56311.027 | I18: =I13+I16 -> 61700.771 | J18: =J13+J16 -> 67037.019
A19: growth | C19: =C18/B18-1 -> 0.1117951 | D19: =D18/C18-1 -> 0.087156095 | E19: =E18/D18-1 -> 0.095791001 | F19: =F18/E18-1 -> 0.11294305 | G19: =G18/F18-1 -> 0.11195454 | H19: =H18/G18-1 -> 0.095781174 | I19: =I18/H18-1 -> 0.095713819 | J19: =J18/I18-1 -> 0.086485926
A20: Subscription mix | B20: =B13/B18 -> 0.92565068 | C20: =C13/C18 -> 0.93344235 | D20: =D13/D18 -> 0.94152263 | E20: =E13/E18 -> 0.94853703 | F20: =F13/F18 -> 0.95468437 | G20: =G13/G18 -> 0.96006193 | H20: =H13/H18 -> 0.96428182 | I20: =I13/I18 -> 0.96805387 | J20: =J13/J18 -> 0.97118489
A22: Billings (cash view of the top line)
A23: Unearned revenue, year-end | B23: 17376 | C23: 19003 | D23: 20743 | E23: 24317 | F23: =BS!F19 -> 27035.752 | G23: =BS!G19 -> 30062.527 | H23: =BS!H19 -> 32941.951 | I23: =BS!I19 -> 36094.951 | J23: =BS!J19 -> 39216.656
A24: Calculated billings = revenue + change in unearned revenue | C24: =C18+C23-B23 -> 36484 | D24: =D18+D23-C23 -> 39635 | E24: =E18+E23-D23 -> 45099 | F24: =F18+F23-E23 -> 48933.712 | G24: =G18+G23-F23 -> 54415.71 | H24: =H18+H23-G23 -> 59190.451 | I24: =I18+I23-H23 -> 64853.771 | J24: =J18+J23-I23 -> 70158.724
A25: billings growth | D25: =D24/C24-1 -> 0.086366626 | E25: =E24/D24-1 -> 0.13785795 | F25: =F24/E24-1 -> 0.08502875 | G25: =G24/F24-1 -> 0.11202908 | H25: =H24/G24-1 -> 0.087745641 | I25: =I24/H24-1 -> 0.095679609 | J25: =J24/I24-1 -> 0.081798692
A27: Guidance check (FY2027)
A28: FY27 revenue guidance - low / high ($mm) | B28: 46100 | C28: 46400
A29: Model FY27E revenue within guidance? | B29: =IF(AND(F18>=B28,F18<=C28),"YES","OUTSIDE") -> YES

Sheet IS
A1: Salesforce - Income Statement (GAAP)
A2: Historicals from 8-K earnings releases (Ex. 99.1). Forecast driven by Assumptions and Revenue Build.
A4: ($ in millions, FY ends Jan 31) | B4: FY2023A | C4: FY2024A | D4: FY2025A | E4: FY2026A | F4: FY2027E | G4: FY2028E | H4: FY2029E | I4: FY2030E | J4: FY2031E
A5: Subscription & support revenue | B5: ='Revenue Build'!B13 -> 29021 | C5: ='Revenue Build'!C13 -> 32537 | D5: ='Revenue Build'!D13 -> 35679 | E5: ='Revenue Build'!E13 -> 39388 | F5: ='Revenue Build'!F13 -> 44120.7 | G5: ='Revenue Build'!G13 -> 49336.56 | H5: ='Revenue Build'!H13 -> 54299.7 | I5: ='Revenue Build'!I13 -> 59729.67 | J5: ='Revenue Build'!J13 -> 65105.34
A6: Professional services & other revenue | B6: ='Revenue Build'!B16 -> 2331 | C6: ='Revenue Build'!C16 -> 2320 | D6: ='Revenue Build'!D16 -> 2216 | E6: ='Revenue Build'!E16 -> 2137 | F6: ='Revenue Build'!F16 -> 2094.26 | G6: ='Revenue Build'!G16 -> 2052.3748 | H6: ='Revenue Build'!H16 -> 2011.3273 | I6: ='Revenue Build'!I16 -> 1971.1008 | J6: ='Revenue Build'!J16 -> 1931.6787
A7: Total revenue | B7: =B5+B6 -> 31352 | C7: =C5+C6 -> 34857 | D7: =D5+D6 -> 37895 | E7: =E5+E6 -> 41525 | F7: =F5+F6 -> 46214.96 | G7: =G5+G6 -> 51388.935 | H7: =H5+H6 -> 56311.027 | I7: =I5+I6 -> 61700.771 | J7: =J5+J6 -> 67037.019
A8: growth | C8: =C7/B7-1 -> 0.1117951 | D8: =D7/C7-1 -> 0.087156095 | E8: =E7/D7-1 -> 0.095791001 | F8: =F7/E7-1 -> 0.11294305 | G8: =G7/F7-1 -> 0.11195454 | H8: =H7/G7-1 -> 0.095781174 | I8: =I7/H7-1 -> 0.095713819 | J8: =J7/I7-1 -> 0.086485926
A10: Cost of revenue - subscription & support | B10: 5821 | C10: 6177 | D10: 6198 | E10: 6796 | F10: =F5*Assumptions!F25 -> 7721.1225 | G10: =G5*Assumptions!G25 -> 8633.898 | H10: =H5*Assumptions!H25 -> 9502.4475 | I10: =I5*Assumptions!I25 -> 10452.692 | J10: =J5*Assumptions!J25 -> 11393.435
A11: Cost of revenue - professional services | B11: 2539 | C11: 2364 | D11: 2445 | E11: 2474 | F11: =F6*Assumptions!F26 -> 2408.399 | G11: =G6*Assumptions!G26 -> 2360.231 | H11: =H6*Assumptions!H26 -> 2313.0264 | I11: =I6*Assumptions!I26 -> 2266.7659 | J11: =J6*Assumptions!J26 -> 2221.4306
A12: Total cost of revenue | B12: =B10+B11 -> 8360 | C12: =C10+C11 -> 8541 | D12: =D10+D11 -> 8643 | E12: =E10+E11 -> 9270 | F12: =F10+F11 -> 10129.522 | G12: =G10+G11 -> 10994.129 | H12: =H10+H11 -> 11815.474 | I12: =I10+I11 -> 12719.458 | J12: =J10+J11 -> 13614.865
A13: Gross profit | B13: =B7-B12 -> 22992 | C13: =C7-C12 -> 26316 | D13: =D7-D12 -> 29252 | E13: =E7-E12 -> 32255 | F13: =F7-F12 -> 36085.438 | G13: =G7-G12 -> 40394.806 | H13: =H7-H12 -> 44495.553 | I13: =I7-I12 -> 48981.313 | J13: =J7-J12 -> 53422.154
A14: Gross margin | B14: =B13/B7 -> 0.73335034 | C14: =C13/C7 -> 0.75497031 | D14: =D13/D7 -> 0.77192242 | E14: =E13/E7 -> 0.77676099 | F14: =F13/F7 -> 0.78081726 | G14: =G13/G7 -> 0.78606038 | H14: =H13/H7 -> 0.79017478 | I14: =I13/I7 -> 0.79385252 | J14: =J13/J7 -> 0.79690527
A16: Research & development | B16: 5055 | C16: 4906 | D16: 5493 | E16: 5993 | F16: =F7*Assumptions!F27 -> 6839.8141 | G16: =G7*Assumptions!G27 -> 7605.5624 | H16: =H7*Assumptions!H27 -> 8334.032 | I16: =I7*Assumptions!I27 -> 9131.7141 | J16: =J7*Assumptions!J27 -> 9921.4788
A17: Sales & marketing | B17: 13526 | C17: 12877 | D17: 13257 | E17: 14345 | F17: =F7*Assumptions!F31 -> 15944.161 | G17: =G7*Assumptions!G31 -> 17472.238 | H17: =H7*Assumptions!H31 -> 18864.194 | I17: =I7*Assumptions!I31 -> 20361.254 | J17: =J7*Assumptions!J31 -> 21787.031
A18: General & administrative | B18: 2553 | C18: 2534 | D18: 2836 | E18: 3000 | F18: =F7*Assumptions!F32 -> 3419.907 | G18: =G7*Assumptions!G32 -> 3751.3922 | H18: =H7*Assumptions!H32 -> 4054.394 | I18: =I7*Assumptions!I32 -> 4380.7547 | J18: =J7*Assumptions!J32 -> 4692.5913
A19: Restructuring | B19: 828 | C19: 988 | D19: 461 | E19: 586 | F19: =F7*Assumptions!F33 -> 462.1496 | G19: =G7*Assumptions!G33 -> 256.94467 | H19: =H7*Assumptions!H33 -> 281.55514 | I19: =I7*Assumptions!I33 -> 308.50385 | J19: =J7*Assumptions!J33 -> 335.1851
A20: Total operating expenses | B20: =SUM(B16:B19) -> 21962 | C20: =SUM(C16:C19) -> 21305 | D20: =SUM(D16:D19) -> 22047 | E20: =SUM(E16:E19) -> 23924 | F20: =SUM(F16:F19) -> 26666.032 | G20: =SUM(G16:G19) -> 29086.137 | H20: =SUM(H16:H19) -> 31534.175 | I20: =SUM(I16:I19) -> 34182.227 | J20: =SUM(J16:J19) -> 36736.286
A21: Operating income (GAAP EBIT) | B21: =B13-B20 -> 1030 | C21: =C13-C20 -> 5011 | D21: =D13-D20 -> 7205 | E21: =E13-E20 -> 8331 | F21: =F13-F20 -> 9419.4066 | G21: =G13-G20 -> 11308.669 | H21: =H13-H20 -> 12961.378 | I21: =I13-I20 -> 14799.086 | J21: =J13-J20 -> 16685.868
A22: GAAP operating margin | B22: =B21/B7 -> 0.032852769 | C22: =C21/C7 -> 0.14375879 | D22: =D21/D7 -> 0.19013062 | E22: =E21/E7 -> 0.20062613 | F22: =F21/F7 -> 0.20381726 | G22: =G21/G7 -> 0.22006038 | H22: =H21/H7 -> 0.23017478 | I22: =I21/I7 -> 0.23985252 | J22: =J21/J7 -> 0.24890527
A24: Gains (losses) on strategic investments | B24: -239 | C24: -277 | D24: -121 | E24: 1017 | F24: =0 -> 0 | G24: =0 -> 0 | H24: =0 -> 0 | I24: =0 -> 0 | J24: =0 -> 0 | K24: Not forecast - volatile mark-to-market
A25: Interest income (on beginning cash + marketable securities) | F25: =Assumptions!F40*(BS!E5+BS!E6) -> 358.6875 | G25: =Assumptions!G40*(BS!F5+BS!F6) -> 673.6903 | H25: =Assumptions!H40*(BS!G5+BS!G6) -> 938.11284 | I25: =Assumptions!I40*(BS!H5+BS!H6) -> 1229.6227 | J25: =Assumptions!J40*(BS!I5+BS!I6) -> 1553.6395
A26: Interest expense (on average debt) | F26: =-Assumptions!F39*AVERAGE(BS!E21,BS!F21) -> -1208.7 | G26: =-Assumptions!G39*AVERAGE(BS!F21,BS!G21) -> -1767.645 | H26: =-Assumptions!H39*AVERAGE(BS!G21,BS!H21) -> -1767.645 | I26: =-Assumptions!I39*AVERAGE(BS!H21,BS!I21) -> -1767.645 | J26: =-Assumptions!J39*AVERAGE(BS!I21,BS!J21) -> -1767.645
A27: Other income (expense), net | B27: -131 | C27: 216 | D27: 354 | E27: 172 | F27: =F25+F26 -> -850.0125 | G27: =G25+G26 -> -1093.9547 | H27: =H25+H26 -> -829.53216 | I27: =I25+I26 -> -538.02234 | J27: =J25+J26 -> -214.00548
A28: Pre-tax income | B28: =B21+B24+B27 -> 660 | C28: =C21+C24+C27 -> 4950 | D28: =D21+D24+D27 -> 7438 | E28: =E21+E24+E27 -> 9520 | F28: =F21+F24+F27 -> 8569.3941 | G28: =G21+G24+G27 -> 10214.714 | H28: =H21+H24+H27 -> 12131.846 | I28: =I21+I24+I27 -> 14261.063 | J28: =J21+J24+J27 -> 16471.862
A29: Provision for income taxes | B29: -452 | C29: -814 | D29: -1241 | E29: -2063 | F29: =-F28*Assumptions!F38 -> -1910.9749 | G29: =-G28*Assumptions!G38 -> -2196.1635 | H29: =-H28*Assumptions!H38 -> -2608.3469 | I29: =-I28*Assumptions!I38 -> -3066.1286 | J29: =-J28*Assumptions!J38 -> -3541.4503
A30: Net income | B30: =B28+B29 -> 208 | C30: =C28+C29 -> 4136 | D30: =D28+D29 -> 6197 | E30: =E28+E29 -> 7457 | F30: =F28+F29 -> 6658.4192 | G30: =G28+G29 -> 8018.5505 | H30: =H28+H29 -> 9523.4991 | I30: =I28+I29 -> 11194.935 | J30: =J28+J29 -> 12930.412
A31: Net margin | B31: =B30/B7 -> 0.0066343455 | C31: =C30/C7 -> 0.11865622 | D31: =D30/D7 -> 0.16353081 | E31: =E30/E7 -> 0.17957857 | F31: =F30/F7 -> 0.14407497 | G31: =G30/G7 -> 0.15603652 | H31: =H30/H7 -> 0.16912316 | I31: =I30/I7 -> 0.18143914 | J31: =J30/J7 -> 0.19288465
A32: Effective tax rate | B32: =-B29/B28 -> 0.68484848 | C32: =-C29/C28 -> 0.16444444 | D32: =-D29/D28 -> 0.16684593 | E32: =-E29/E28 -> 0.21670168 | F32: =-F29/F28 -> 0.223 | G32: =-G29/G28 -> 0.215 | H32: =-H29/H28 -> 0.215 | I32: =-I29/I28 -> 0.215 | J32: =-J29/J28 -> 0.215
A34: Diluted shares (mm) | B34: 997 | C34: 984 | D34: 974 | E34: 956 | F34: =Assumptions!F58 -> 838 | G34: =F34*(1+Assumptions!G59) -> 825.43 | H34: =G34*(1+Assumptions!H59) -> 813.04855 | I34: =H34*(1+Assumptions!I59) -> 800.85282 | J34: =I34*(1+Assumptions!J59) -> 788.84003
A35: Diluted EPS (GAAP, $) | B35: =B30/B34 -> 0.20862588 | C35: =C30/C34 -> 4.203252 | D35: =D30/D34 -> 6.362423 | E35: =E30/E34 -> 7.8002092 | F35: =F30/F34 -> 7.9456076 | G35: =G30/G34 -> 9.7143919 | H35: =H30/H34 -> 11.713322 | I35: =I30/I34 -> 13.978767 | J35: =J30/J34 -> 16.391678
A37: Memo items
A38: Stock-based compensation (in opex above) | B38: 3279 | C38: 2787 | D38: 3183 | E38: 3509 | F38: =F7*Assumptions!F34 -> 3835.8417 | G38: =G7*Assumptions!G34 -> 4265.2816 | H38: =H7*Assumptions!H34 -> 4673.8153 | I38: =I7*Assumptions!I34 -> 5121.164 | J38: =J7*Assumptions!J34 -> 5564.0726
A39: Amortization of acquired intangibles | D39: 1651 | E39: 1687 | F39: =MIN(Assumptions!F35,BS!E14) -> 1900 | G39: =MIN(Assumptions!G35,BS!F14) -> 1700 | H39: =MIN(Assumptions!H35,BS!G14) -> 1500 | I39: =MIN(Assumptions!I35,BS!H14) -> 1200 | J39: =MIN(Assumptions!J35,BS!I14) -> 515
A40: Depreciation (forecast: owned PP&E only; excl. lease ROU amortization) | D40: =D41-D39 -> 1826 | E40: =E41-E39 -> 1944 | F40: =Assumptions!F36*BS!E10 -> 624 | G40: =Assumptions!G36*BS!F10 -> 637.84488 | H40: =Assumptions!H36*BS!G10 -> 664.44271 | I40: =Assumptions!I36*BS!H10 -> 700.48725 | J40: =Assumptions!J36*BS!I10 -> 745.49211
A41: Total D&A | B41: 3786 | C41: 3959 | D41: 3477 | E41: 3631 | F41: =F39+F40 -> 2524 | G41: =G39+G40 -> 2337.8449 | H41: =H39+H40 -> 2164.4427 | I41: =I39+I40 -> 1900.4872 | J41: =J39+J40 -> 1260.4921
A42: EBITDA (GAAP EBIT + D&A; SBC treated as expense) | B42: =B21+B41 -> 4816 | C42: =C21+C41 -> 8970 | D42: =D21+D41 -> 10682 | E42: =E21+E41 -> 11962 | F42: =F21+F41 -> 11943.407 | G42: =G21+G41 -> 13646.514 | H42: =H21+H41 -> 15125.821 | I42: =I21+I41 -> 16699.573 | J42: =J21+J41 -> 17946.36
A43: Non-GAAP operating income (EBIT + SBC + amortization + restructuring) | D43: =D21+D38+D39+D19 -> 12500 | E43: =E21+E38+E39+E19 -> 14113 | F43: =F21+F38+F39+F19 -> 15617.398 | G43: =G21+G38+G39+G19 -> 17530.895 | H43: =H21+H38+H39+H19 -> 19416.749 | I43: =I21+I38+I39+I19 -> 21428.753 | J43: =J21+J38+J39+J19 -> 23100.125
A44: Non-GAAP operating margin | D44: =D43/D7 -> 0.32985882 | E44: =E43/E7 -> 0.33986755 | F44: =F43/F7 -> 0.33792949 | G44: =G43/G7 -> 0.34114143 | H44: =H43/H7 -> 0.34481254 | I44: =I43/I7 -> 0.34730123 | J44: =J43/J7 -> 0.3445876

Sheet BS
A1: Salesforce - Balance Sheet
A2: FY25A/FY26A from Q4 FY26 release. Some lines combined (current + noncurrent). FY23A/FY24A not shown.
A4: ($ in millions, FY ends Jan 31) | B4: FY2023A | C4: FY2024A | D4: FY2025A | E4: FY2026A | F4: FY2027E | G4: FY2028E | H4: FY2029E | I4: FY2030E | J4: FY2031E
A5: Cash & cash equivalents | D5: 8848 | E5: 7327 | F5: =CF!F30 -> 15727.075 | G5: =CF!G30 -> 22778.342 | H5: =CF!H30 -> 30551.938 | I5: =CF!I30 -> 39192.387 | J5: =CF!J30 -> 48469.317
A6: Marketable securities | D6: 5184 | E6: 2238 | F6: =E6 -> 2238 | G6: =F6 -> 2238 | H6: =G6 -> 2238 | I6: =H6 -> 2238 | J6: =I6 -> 2238
A7: Accounts receivable, net | D7: 11945 | E7: 14339 | F7: =IS!F7*Assumptions!F43/365 -> 15953.657 | G7: =IS!G7*Assumptions!G43/365 -> 17739.742 | H7: =IS!H7*Assumptions!H43/365 -> 19438.875 | I7: =IS!I7*Assumptions!I43/365 -> 21299.444 | J7: =IS!J7*Assumptions!J43/365 -> 23141.546
A8: Prepaid expenses & other current assets | D8: 1779 | E8: 2243 | F8: =IS!F7*Assumptions!F45 -> 2495.6078 | G8: =IS!G7*Assumptions!G45 -> 2775.0025 | H8: =IS!H7*Assumptions!H45 -> 3040.7955 | I8: =IS!I7*Assumptions!I45 -> 3331.8416 | J8: =IS!J7*Assumptions!J45 -> 3619.999
A9: Capitalized contract costs (current + noncurrent) | D9: 4446 | E9: 5060 | F9: =IS!F7*Assumptions!F44 -> 5638.2251 | G9: =IS!G7*Assumptions!G44 -> 6269.45 | H9: =IS!H7*Assumptions!H44 -> 6869.9453 | I9: =IS!I7*Assumptions!I44 -> 7527.494 | J9: =IS!J7*Assumptions!J44 -> 8178.5163
A10: Property & equipment, net | D10: 3236 | E10: 3120 | F10: =E10-CF!F16-IS!F40 -> 3189.2244 | G10: =F10-CF!G16-IS!G40 -> 3322.2135 | H10: =G10-CF!H16-IS!H40 -> 3502.4362 | I10: =H10-CF!I16-IS!I40 -> 3727.4606 | J10: =I10-CF!J16-IS!J40 -> 3987.5237
A11: Operating lease right-of-use assets | D11: 2157 | E11: 2003 | F11: =E11 -> 2003 | G11: =F11 -> 2003 | H11: =G11 -> 2003 | I11: =H11 -> 2003 | J11: =I11 -> 2003
A12: Strategic investments | D12: 4852 | E12: 7591 | F12: =E12 -> 7591 | G12: =F12 -> 7591 | H12: =G12 -> 7591 | I12: =H12 -> 7591 | J12: =I12 -> 7591
A13: Goodwill | D13: 51283 | E13: 57941 | F13: =E13-CF!F17 -> 59445 | G13: =F13-CF!G17 -> 59445 | H13: =G13-CF!H17 -> 59445 | I13: =H13-CF!I17 -> 59445 | J13: =I13-CF!J17 -> 59445
A14: Intangible assets acquired, net | D14: 4428 | E14: 6815 | F14: =E14-IS!F39 -> 4915 | G14: =F14-IS!G39 -> 3215 | H14: =G14-IS!H39 -> 1715 | I14: =H14-IS!I39 -> 515 | J14: =I14-IS!J39 -> 0
A15: Deferred tax & other assets | D15: 4770 | E15: 3628 | F15: =E15 -> 3628 | G15: =F15 -> 3628 | H15: =G15 -> 3628 | I15: =H15 -> 3628 | J15: =I15 -> 3628
A16: Total assets | D16: =SUM(D5:D15) -> 102928 | E16: =SUM(E5:E15) -> 112305 | F16: =SUM(F5:F15) -> 122823.79 | G16: =SUM(G5:G15) -> 131004.75 | H16: =SUM(H5:H15) -> 140023.99 | I16: =SUM(I5:I15) -> 150498.63 | J16: =SUM(J5:J15) -> 162301.9
A18: AP, accrued expenses & other liabilities | D18: 6658 | E18: 8253 | F18: =IS!F7*Assumptions!F46 -> 9196.777 | G18: =IS!G7*Assumptions!G46 -> 10226.398 | H18: =IS!H7*Assumptions!H46 -> 11205.894 | I18: =IS!I7*Assumptions!I46 -> 12278.453 | J18: =IS!J7*Assumptions!J46 -> 13340.367
A19: Unearned revenue | D19: 20743 | E19: 24317 | F19: =IS!F7*Assumptions!F47 -> 27035.752 | G19: =IS!G7*Assumptions!G47 -> 30062.527 | H19: =IS!H7*Assumptions!H47 -> 32941.951 | I19: =IS!I7*Assumptions!I47 -> 36094.951 | J19: =IS!J7*Assumptions!J47 -> 39216.656
A20: Operating lease liabilities (current + noncurrent) | D20: 2959 | E20: 2737 | F20: =E20 -> 2737 | G20: =F20 -> 2737 | H20: =G20 -> 2737 | I20: =H20 -> 2737 | J20: =I20 -> 2737
A21: Total debt (current + noncurrent) | D21: 8433 | E21: 14439 | F21: =E21+CF!F21+CF!F22 -> 39281 | G21: =F21+CF!G21+CF!G22 -> 39281 | H21: =G21+CF!H21+CF!H22 -> 39281 | I21: =H21+CF!I21+CF!I22 -> 39281 | J21: =I21+CF!J21+CF!J22 -> 39281
A22: Other noncurrent liabilities | D22: 2962 | E22: 3417 | F22: =E22 -> 3417 | G22: =F22 -> 3417 | H22: =G22 -> 3417 | I22: =H22 -> 3417 | J22: =I22 -> 3417
A23: Total liabilities | D23: =SUM(D18:D22) -> 41755 | E23: =SUM(E18:E22) -> 53163 | F23: =SUM(F18:F22) -> 81667.529 | G23: =SUM(G18:G22) -> 85723.925 | H23: =SUM(H18:H22) -> 89582.845 | I23: =SUM(I18:I22) -> 93808.404 | J23: =SUM(J18:J22) -> 97992.023
A25: Paid-in capital, common stock & AOCI | D25: 64311 | E25: 69149 | F25: =E25+IS!F38+CF!F25 -> 73984.842 | G25: =F25+IS!G38+CF!G25 -> 79250.123 | H25: =G25+IS!H38+CF!H25 -> 84923.939 | I25: =H25+IS!I38+CF!I25 -> 91045.103 | J25: =I25+IS!J38+CF!J25 -> 97609.175
A26: Treasury stock | D26: -19507 | E26: -32228 | F26: =E26+CF!F23 -> -60228 | G26: =F26+CF!G23 -> -67833.268 | H26: =G26+CF!H23 -> -76238.563 | I26: =H26+CF!I23 -> -85592.298 | J26: =I26+CF!J23 -> -95668.177
A27: Retained earnings | D27: 16369 | E27: 22221 | F27: =E27+IS!F30+CF!F24 -> 27399.419 | G27: =F27+IS!G30+CF!G24 -> 33863.97 | H27: =G27+IS!H30+CF!H24 -> 41755.769 | I27: =H27+IS!I30+CF!I24 -> 51237.418 | J27: =I27+IS!J30+CF!J24 -> 62368.881
A28: Total stockholders' equity | D28: =SUM(D25:D27) -> 61173 | E28: =SUM(E25:E27) -> 59142 | F28: =SUM(F25:F27) -> 41156.261 | G28: =SUM(G25:G27) -> 45280.825 | H28: =SUM(H25:H27) -> 50441.144 | I28: =SUM(I25:I27) -> 56690.223 | J28: =SUM(J25:J27) -> 64309.879
A29: Total liabilities & equity | D29: =D23+D28 -> 102928 | E29: =E23+E28 -> 112305 | F29: =F23+F28 -> 122823.79 | G29: =G23+G28 -> 131004.75 | H29: =H23+H28 -> 140023.99 | I29: =I23+I28 -> 150498.63 | J29: =J23+J28 -> 162301.9
A31: BALANCE CHECK (assets - liabilities - equity; must be 0) | D31: =ROUND(D16-D29,3) -> 0 | E31: =ROUND(E16-E29,3) -> 0 | F31: =ROUND(F16-F29,3) -> 0 | G31: =ROUND(G16-G29,3) -> 0 | H31: =ROUND(H16-H29,3) -> 0 | I31: =ROUND(I16-I29,3) -> 0 | J31: =ROUND(J16-J29,3) -> 0
A33: Memo: net cash / (net debt) incl. marketable securities | D33: =D5+D6-D21 -> 5599 | E33: =E5+E6-E21 -> -4874 | F33: =F5+F6-F21 -> -21315.925 | G33: =G5+G6-G21 -> -14264.658 | H33: =H5+H6-H21 -> -6491.0624 | I33: =I5+I6-I21 -> 2149.3873 | J33: =J5+J6-J21 -> 11426.317
A34: Memo: total debt / EBITDA | D34: =D21/IS!D42 -> 0.7894589 | E34: =E21/IS!E42 -> 1.2070724 | F34: =F21/IS!F42 -> 3.2889276 | G34: =G21/IS!G42 -> 2.8784641 | H34: =H21/IS!H42 -> 2.59695 | I34: =I21/IS!I42 -> 2.3522158 | J34: =J21/IS!J42 -> 2.1888005

Sheet CF
A1: Salesforce - Cash Flow Statement
A2: Historicals show key lines only; 'other operating' is the reconciling item to reported CFO.
A4: ($ in millions, FY ends Jan 31) | B4: FY2023A | C4: FY2024A | D4: FY2025A | E4: FY2026A | F4: FY2027E | G4: FY2028E | H4: FY2029E | I4: FY2030E | J4: FY2031E
A5: Net income | B5: =IS!B30 -> 208 | C5: =IS!C30 -> 4136 | D5: =IS!D30 -> 6197 | E5: =IS!E30 -> 7457 | F5: =IS!F30 -> 6658.4192 | G5: =IS!G30 -> 8018.5505 | H5: =IS!H30 -> 9523.4991 | I5: =IS!I30 -> 11194.935 | J5: =IS!J30 -> 12930.412
A6: Depreciation & amortization | B6: =IS!B41 -> 3786 | C6: =IS!C41 -> 3959 | D6: =IS!D41 -> 3477 | E6: =IS!E41 -> 3631 | F6: =IS!F41 -> 2524 | G6: =IS!G41 -> 2337.8449 | H6: =IS!H41 -> 2164.4427 | I6: =IS!I41 -> 1900.4872 | J6: =IS!J41 -> 1260.4921
A7: Stock-based compensation (non-cash add-back) | B7: =IS!B38 -> 3279 | C7: =IS!C38 -> 2787 | D7: =IS!D38 -> 3183 | E7: =IS!E38 -> 3509 | F7: =IS!F38 -> 3835.8417 | G7: =IS!G38 -> 4265.2816 | H7: =IS!H38 -> 4673.8153 | I7: =IS!I38 -> 5121.164 | J7: =IS!J38 -> 5564.0726
A8: (Increase) / decrease in accounts receivable | F8: =BS!E7-BS!F7 -> -1614.6574 | G8: =BS!F7-BS!G7 -> -1786.0845 | H8: =BS!G7-BS!H7 -> -1699.1333 | I8: =BS!H7-BS!I7 -> -1860.569 | J8: =BS!I7-BS!J7 -> -1842.1021
A9: (Increase) / decrease in prepaid & other | F9: =BS!E8-BS!F8 -> -252.60784 | G9: =BS!F8-BS!G8 -> -279.39464 | H9: =BS!G8-BS!H8 -> -265.793 | I9: =BS!H8-BS!I8 -> -291.04615 | J9: =BS!I8-BS!J8 -> -288.15741
A10: (Increase) / decrease in capitalized contract costs | F10: =BS!E9-BS!F9 -> -578.22512 | G10: =BS!F9-BS!G9 -> -631.22493 | H10: =BS!G9-BS!H9 -> -600.49529 | I10: =BS!H9-BS!I9 -> -657.5487 | J10: =BS!I9-BS!J9 -> -651.02229
A11: Increase / (decrease) in AP & accrued | F11: =BS!F18-BS!E18 -> 943.77704 | G11: =BS!G18-BS!F18 -> 1029.621 | H11: =BS!H18-BS!G18 -> 979.49641 | I11: =BS!I18-BS!H18 -> 1072.5589 | J11: =BS!J18-BS!I18 -> 1061.9134
A12: Increase / (decrease) in unearned revenue | B12: 1744 | C12: 1623 | D12: 1584 | E12: 2924 | F12: =BS!F19-BS!E19 -> 2718.7516 | G12: =BS!G19-BS!F19 -> 3026.7753 | H12: =BS!H19-BS!G19 -> 2879.4241 | I12: =BS!I19-BS!H19 -> 3152.9999 | J12: =BS!J19-BS!I19 -> 3121.7052
A13: Other operating items, net (historical reconciling item) | B13: =B15-SUM(B5:B12) -> -1906 | C13: =C15-SUM(C5:C12) -> -2271 | D13: =D15-SUM(D5:D12) -> -1349 | E13: =E15-SUM(E5:E12) -> -2525 | F13: =0 -> 0 | G13: =0 -> 0 | H13: =0 -> 0 | I13: =0 -> 0 | J13: =0 -> 0
A14: Cash from operations (CFO) | B14: =SUM(B5:B13) -> 7111 | C14: =SUM(C5:C13) -> 10234 | D14: =SUM(D5:D13) -> 13092 | E14: =SUM(E5:E13) -> 14996 | F14: =SUM(F5:F13) -> 14235.299 | G14: =SUM(G5:G13) -> 15981.369 | H14: =SUM(H5:H13) -> 17655.256 | I14: =SUM(I5:I13) -> 19632.981 | J14: =SUM(J5:J13) -> 21157.313
A15: Memo: reported CFO | B15: 7111 | C15: 10234 | D15: 13092 | E15: 14996
A16: Capital expenditures | B16: -798 | C16: -736 | D16: -658 | E16: -594 | F16: =-IS!F7*Assumptions!F37 -> -693.2244 | G16: =-IS!G7*Assumptions!G37 -> -770.83402 | H16: =-IS!H7*Assumptions!H37 -> -844.66541 | I16: =-IS!I7*Assumptions!I37 -> -925.51156 | J16: =-IS!J7*Assumptions!J37 -> -1005.5553
A17: Acquisitions, net of cash | D17: -2734 | E17: -9268 | F17: =-Assumptions!F50 -> -1504 | G17: =-Assumptions!G50 -> 0 | H17: =-Assumptions!H50 -> 0 | I17: =-Assumptions!I50 -> 0 | J17: =-Assumptions!J50 -> 0
A18: Net (purchases) / sales of investments | F18: =(BS!E6-BS!F6)+(BS!E12-BS!F12) -> 0 | G18: =(BS!F6-BS!G6)+(BS!F12-BS!G12) -> 0 | H18: =(BS!G6-BS!H6)+(BS!G12-BS!H12) -> 0 | I18: =(BS!H6-BS!I6)+(BS!H12-BS!I12) -> 0 | J18: =(BS!I6-BS!J6)+(BS!I12-BS!J12) -> 0
A19: Cash from investing (CFI) | F19: =SUM(F16:F18) -> -2197.2244 | G19: =SUM(G16:G18) -> -770.83402 | H19: =SUM(H16:H18) -> -844.66541 | I19: =SUM(I16:I18) -> -925.51156 | J19: =SUM(J16:J18) -> -1005.5553
A21: Debt issuance | D21: 0 | E21: 6000 | F21: =Assumptions!F51 -> 24842 | G21: =Assumptions!G51 -> 0 | H21: =Assumptions!H51 -> 0 | I21: =Assumptions!I51 -> 0 | J21: =Assumptions!J51 -> 0
A22: Debt repayment | D22: -1000 | E22: 0 | F22: =-Assumptions!F52 -> 0 | G22: =-Assumptions!G52 -> 0 | H22: =-Assumptions!H52 -> 0 | I22: =-Assumptions!I52 -> 0 | J22: =-Assumptions!J52 -> 0
A23: Share repurchases | B23: -4000 | C23: -7620 | D23: -7829 | E23: -12596 | F23: =-Assumptions!F53 -> -28000 | G23: =-Assumptions!G54*MAX(G32,0) -> -7605.2676 | H23: =-Assumptions!H54*MAX(H32,0) -> -8405.2953 | I23: =-Assumptions!I54*MAX(I32,0) -> -9353.7347 | J23: =-Assumptions!J54*MAX(J32,0) -> -10075.879
A24: Dividends | B24: 0 | C24: 0 | D24: -1537 | E24: -1587 | F24: =-Assumptions!F55 -> -1480 | G24: =F24*(1+Assumptions!G56) -> -1554 | H24: =G24*(1+Assumptions!H56) -> -1631.7 | I24: =H24*(1+Assumptions!I56) -> -1713.285 | J24: =I24*(1+Assumptions!J56) -> -1798.9492
A25: Proceeds from employee stock plans | D25: 1540 | E25: 1039 | F25: =Assumptions!F57 -> 1000 | G25: =Assumptions!G57 -> 1000 | H25: =Assumptions!H57 -> 1000 | I25: =Assumptions!I57 -> 1000 | J25: =Assumptions!J57 -> 1000
A26: Cash from financing (CFF) | F26: =SUM(F21:F25) -> -3638 | G26: =SUM(G21:G25) -> -8159.2676 | H26: =SUM(H21:H25) -> -9036.9953 | I26: =SUM(I21:I25) -> -10067.02 | J26: =SUM(J21:J25) -> -10874.828
A28: Net change in cash | F28: =F14+F19+F26 -> 8400.0747 | G28: =G14+G19+G26 -> 7051.2676 | H28: =H14+H19+H26 -> 7773.5953 | I28: =I14+I19+I26 -> 8640.4497 | J28: =J14+J19+J26 -> 9276.9297
A29: Beginning cash | F29: =BS!E5 -> 7327 | G29: =BS!F5 -> 15727.075 | H29: =BS!G5 -> 22778.342 | I29: =BS!H5 -> 30551.938 | J29: =BS!I5 -> 39192.387
A30: Ending cash | F30: =F29+F28 -> 15727.075 | G30: =G29+G28 -> 22778.342 | H30: =H29+H28 -> 30551.938 | I30: =I29+I28 -> 39192.387 | J30: =J29+J28 -> 48469.317
A32: Free cash flow (CFO - capex) | B32: =B14+B16 -> 6313 | C32: =C14+C16 -> 9498 | D32: =D14+D16 -> 12434 | E32: =E14+E16 -> 14402 | F32: =F14+F16 -> 13542.075 | G32: =G14+G16 -> 15210.535 | H32: =H14+H16 -> 16810.591 | I32: =I14+I16 -> 18707.469 | J32: =J14+J16 -> 20151.758
A33: FCF margin | B33: =B32/IS!B7 -> 0.20135876 | C33: =C32/IS!C7 -> 0.27248472 | D33: =D32/IS!D7 -> 0.32811717 | E33: =E32/IS!E7 -> 0.34682721 | F33: =F32/IS!F7 -> 0.29302362 | G33: =G32/IS!G7 -> 0.29598853 | H33: =H32/IS!H7 -> 0.29853106 | I33: =I32/IS!I7 -> 0.30319669 | J33: =J32/IS!J7 -> 0.30060641
A34: FCF growth | C34: =C32/B32-1 -> 0.50451449 | D34: =D32/C32-1 -> 0.30911771 | E34: =E32/D32-1 -> 0.1582757 | F34: =F32/E32-1 -> -0.059708739 | G34: =G32/F32-1 -> 0.12320567 | H34: =H32/G32-1 -> 0.10519389 | I34: =I32/H32-1 -> 0.11283832 | J34: =J32/I32-1 -> 0.077203842
A35: FCF after SBC (treating SBC as a cash cost) | B35: =B32-B7 -> 3034 | C35: =C32-C7 -> 6711 | D35: =D32-D7 -> 9251 | E35: =E32-E7 -> 10893 | F35: =F32-F7 -> 9706.2331 | G35: =G32-G7 -> 10945.254 | H35: =H32-H7 -> 12136.775 | I35: =I32-I7 -> 13586.305 | J35: =J32-J7 -> 14587.685

Sheet DCF
A1: Salesforce - Unlevered DCF Valuation
A2: Mid-year convention. FY27 includes only the cash flow after the Jul-31-2026 balance sheet date.
A4: Market & balance sheet inputs
A5: Valuation date | B5: 46309
A6: Share price ($) | B6: 235.95 | K6: NYSE close Oct 14, 2026 (stockanalysis.com)
A7: Basic shares outstanding (mm) | B7: 823 | K7: Post-ASR; stockanalysis.com Oct 2026
A8: Dilutive securities (mm) | B8: 7 | K8: Estimate for RSUs/options (treasury method)
A9: Diluted shares (mm) | B9: =B7+B8 -> 830
A10: Balance sheet date for net debt | B10: 46234 | K10: Latest 10-Q: Q2 FY27
A11: Cash & cash equivalents | B11: 8310 | K11: Q2 FY27 balance sheet
A12: Marketable securities | B12: 3093 | K12: Q2 FY27 balance sheet
A13: Strategic investments (book) | B13: 11324 | K13: Q2 FY27 balance sheet; mostly private stakes
A14: Haircut on strategic investments | B14: 0.2 | K14: Illiquid private holdings - conservative haircut
A15: Total debt | B15: 39288 | K15: Q2 FY27: $0 current + $39,288mm noncurrent (post-ASR)
A16: Treat SBC as a real cost? (1 = yes, 0 = add back) | B16: 1 | K16: 1 = do NOT add SBC back to FCF (conservative, dilution is real). 0 = sell-side style add-back
A18: Discount rate (WACC)
A19: Risk-free rate (10Y UST) | B19: 0.052 | K19: 10Y Treasury ~5.19-5.24%, Oct 9-13, 2026
A20: Equity risk premium | B20: 0.05 | K20: Damodaran-style implied ERP range 4.5-5.5%
A21: Levered beta | B21: 1.26 | K21: 5Y monthly beta, stockanalysis.com
A22: Cost of equity (CAPM) | B22: =B19+B21*B20 -> 0.115
A23: Pre-tax cost of debt | B23: 0.055 | K23: ~Rf + 30bp spread for A-rated issuer
A24: Tax rate | B24: 0.21 | K24: US federal statutory
A25: After-tax cost of debt | B25: =B23*(1-B24) -> 0.04345
A26: Market value of equity | B26: =B6*B9 -> 195838.5
A27: Debt | B27: =B15 -> 39288
A28: Equity weight | B28: =B26/(B26+B27) -> 0.83290697
A29: Debt weight | B29: =B27/(B26+B27) -> 0.16709303
A30: WACC | B30: =B28*B22+B29*B25 -> 0.10304449
A32: Terminal value inputs
A33: Perpetuity growth rate | B33: 0.03 | K33: Nominal; below long-run nominal GDP
A34: Exit EV / EBITDA multiple (on FY31 GAAP EBITDA) | B34: 16 | K34: CRM trades ~17-18x FY27E GAAP EBITDA today; assume some compression by FY31
A35: Weight on perpetuity method in blended value | B35: 0.5
A37: Unlevered free cash flow ($mm) | F37: FY2027E | G37: FY2028E | H37: FY2029E | I37: FY2030E | J37: FY2031E
A38: Fiscal year-end date | F38: =DATE(2027,1,31) -> 46418 | G38: =DATE(2028,1,31) -> 46783 | H38: =DATE(2029,1,31) -> 47149 | I38: =DATE(2030,1,31) -> 47514 | J38: =DATE(2031,1,31) -> 47879
A39: Revenue | F39: =IS!F7 -> 46214.96 | G39: =IS!G7 -> 51388.935 | H39: =IS!H7 -> 56311.027 | I39: =IS!I7 -> 61700.771 | J39: =IS!J7 -> 67037.019
A40: EBIT (GAAP, after SBC expense) | F40: =IS!F21 -> 9419.4066 | G40: =IS!G21 -> 11308.669 | H40: =IS!H21 -> 12961.378 | I40: =IS!I21 -> 14799.086 | J40: =IS!J21 -> 16685.868
A41: Less: taxes on EBIT | F41: =-F40*Assumptions!F38 -> -2100.5277 | G41: =-G40*Assumptions!G38 -> -2431.3638 | H41: =-H40*Assumptions!H38 -> -2786.6963 | I41: =-I40*Assumptions!I38 -> -3181.8034 | J41: =-J40*Assumptions!J38 -> -3587.4615
A42: NOPAT | F42: =F40+F41 -> 7318.8789 | G42: =G40+G41 -> 8877.3049 | H42: =H40+H41 -> 10174.682 | I42: =I40+I41 -> 11617.282 | J42: =J40+J41 -> 13098.406
A43: Plus: D&A | F43: =IS!F41 -> 2524 | G43: =IS!G41 -> 2337.8449 | H43: =IS!H41 -> 2164.4427 | I43: =IS!I41 -> 1900.4872 | J43: =IS!J41 -> 1260.4921
A44: Plus: SBC add-back (only if B16 = 0) | F44: =IS!F38*(1-$B$16) -> 0 | G44: =IS!G38*(1-$B$16) -> 0 | H44: =IS!H38*(1-$B$16) -> 0 | I44: =IS!I38*(1-$B$16) -> 0 | J44: =IS!J38*(1-$B$16) -> 0
...

Sheet Sources
A1: Sources
A3: FY2026 & FY2025 financial statements, RPO, FY27 initial guidance | B3: Salesforce Q4 FY26 earnings release, 8-K Ex. 99.1 (Feb 25, 2026): https://www.sec.gov/Archives/edgar/data/1108524/000110852426000056/crm-q4fy26xexhibit991.htm
A4: FY2024 & FY2023 financial statements, RPO | B4: Salesforce Q4 FY24 earnings release, 8-K Ex. 99.1 (Feb 28, 2024): https://www.sec.gov/Archives/edgar/data/1108524/000110852424000002/crm-q4fy24xexhibit991.htm
A5: Q2 FY27 balance sheet (Jul 31, 2026), ASR, debt, raised FY27 guidance | B5: Salesforce Q2 FY27 earnings release (Aug 26, 2026): https://investor.salesforce.com/files/doc_financials/2027/q2/CRM-Q2-FY27-Earnings-Press-Release.pdf
A6: Share price, shares outstanding, beta | B6: stockanalysis.com/stocks/crm (close Oct 14, 2026)
A7: 10-year Treasury yield | B7: themortgagereports.com (Oct 13, 2026: 5.19%); etfdb.com (Oct 9, 2026: 5.24%)
A9: Combined balance sheet lines | B9: Capitalized contract costs, operating lease liabilities and debt combine current + noncurrent. 'Paid-in capital, common stock & AOCI' = common stock + APIC + AOCI.
A10: Not verified from primary source | B10: Strategic-investment haircut, ERP, cost of debt, dilutive securities and all forecast drivers are analyst judgment - change them on Assumptions / DCF.
